sample_data/ETHBTC/2020-11-01T09-00-00_trades.json
[{"e": "aggTrade", "E": 1604221202529, "s": "ETHBTC", "a": 178113193, "p": "0.02818200", "q": "2.02000000", "f": 199140696, "l": 199140696, "T": 1604221202527, "m": false, "M": true}, {"e": "aggTrade", "E": 1604221203060, "s": "ETHBTC", "a": 178113194, "p": "0.02818200", "q": "5.00000000", "f": 199140697, "l": 199140698, "T": 1604221203058, "m": false, "M": true}, {"e": "aggTrade", "E": 1604221211768, "s": "ETHBTC", "a": 178113195, "p": "0.02818100", "q": "5.00000000", "f": 199140699, "l": 199140700, "T": 1604221211766, "m": true, "M": true}, {"e": "aggTrade", "E": 1604221211873, "s": "ETHBTC", "a": 178113196, "p": "0.02818100", "q": "2.50000000", "f": 199140701, "l": 199140701, "T": 1604221211872, "m": true, "M": true}, {"e": "aggTrade", "E": 1604221212073, "s": "ETHBTC", "a": 178113197, "p": "0.02817900", "q": "5.41700000", "f": 199140702, "l": 199140702, "T": 1604221212072, "m": true, "M": true}, {"e": "aggTrade", "E": 1604221212246, "s": "ETHBTC", "a": 178113198, "p": "0.02817800", "q": "3.00000000", "f": 199140703, "l": 199140703, "T": 1604221212245, "m": true, "M": true}, {"e": "aggTrade", "E": 1604221212562, "s": "ETHBTC", "a": 178113199, "p": "0.02817700", "q": "3.00000000", "f": 199140704, "l": 199140704, "T": 1604221212560, "m": true, "M": true}, {"e": "aggTrade", "E": 1604221213836, "s": "ETHBTC", "a": 178113200, "p": "0.02817600", "q": "3.11200000", "f": 199140705, "l": 199140705, "T": 1604221213834, "m": true, "M": true}, {"e": "aggTrade", "E": 1604221216395, "s": "ETHBTC", "a": 178113201, "p": "0.02817600", "q": "5.00000000", "f": 199140706, "l": 199140707, "T": 1604221216393, "m": true, "M": true}, {"e": "aggTrade", "E": 1604221220175, "s": "ETHBTC", "a": 178113202, "p": "0.02817800", "q": "0.10000000", "f": 199140708, "l": 199140708, "T": 1604221220173, "m": false, "M": true}, {"e": "aggTrade", "E": 1604221226056, "s": "ETHBTC", "a": 178113203, "p": "0.02817700", "q": "0.00500000", "f": 199140709, "l": 199140709, "T": 1604221226055, "m": true, "M": true}, {"e": "aggTrade", "E": 1604221230474, "s": "ETHBTC", "a": 178113204, "p": "0.02818000", "q": "6.04000000", "f": 199140710, "l": 199140710, "T": 1604221230473, "m": true, "M": true}, {"e": "aggTrade", "E": 1604221230726, "s": "ETHBTC", "a": 178113205, "p": "0.02817900", "q": "0.00400000", "f": 199140711, "l": 199140711, "T": 1604221230725, "m": false, "M": true}, {"e": "aggTrade", "E": 1604221234591, "s": "ETHBTC", "a": 178113206, "p": "0.02818100", "q": "2.14000000", "f": 199140712, "l": 199140712, "T": 1604221234590, "m": false, "M": true}, {"e": "aggTrade", "E": 1604221240412, "s": "ETHBTC", "a": 178113207, "p": "0.02817800", "q": "0.94000000", "f": 199140713, "l": 199140713, "T": 1604221240410, "m": false, "M": true}, {"e": "aggTrade", "E": 1604221246791, "s": "ETHBTC", "a": 178113208, "p": "0.02817900", "q": "0.27700000", "f": 199140714, "l": 199140714, "T": 1604221246790, "m": true, "M": true}, {"e": "aggTrade", "E": 1604221247616, "s": "ETHBTC", "a": 178113209, "p": "0.02817800", "q": "0.31900000", "f": 199140715, "l": 199140715, "T": 1604221247614, "m": true, "M": true}, {"e": "aggTrade", "E": 1604221247717, "s": "ETHBTC", "a": 178113210, "p": "0.02817800", "q": "0.31900000", "f": 199140716, "l": 199140716, "T": 1604221247716, "m": true, "M": true}, {"e": "aggTrade", "E": 1604221248957, "s": "ETHBTC", "a": 178113211, "p": "0.02818000", "q": "0.16600000", "f": 199140717, "l": 199140717, "T": 1604221248955, "m": false, "M": true}, {"e": "aggTrade", "E": 1604221260355, "s": "ETHBTC", "a": 178113212, "p": "0.02818000", "q": "0.44700000", "f": 199140718, "l": 199140718, "T": 1604221260354, "m": false, "M": true}, {"e": "aggTrade", "E": 1604221262653, "s": "ETHBTC", "a": 178113213, "p": "0.02817900", "q": "0.00400000", "f": 199140719, "l": 199140719, "T": 1604221262652, "m": false, "M": true}, {"e": "aggTrade", "E": 1604221273602, "s": "ETHBTC", "a": 178113214, "p": "0.02817600", "q": "4.12800000", "f": 199140720, "l": 199140720, "T": 1604221273600, "m": true, "M": true}, {"e": "aggTrade", "E": 1604221273700, "s": "ETHBTC", "a": 178113215, "p": "0.02817600", "q": "2.69600000", "f": 199140721, "l": 199140722, "T": 1604221273698, "m": true, "M": true}, {"e": "aggTrade", "E": 1604221282595, "s": "ETHBTC", "a": 178113216, "p": "0.02817600", "q": "0.00400000", "f": 199140723, "l": 199140723, "T": 1604221282594, "m": false, "M": true}, {"e": "aggTrade", "E": 1604221294656, "s": "ETHBTC", "a": 178113217, "p": "0.02817500", "q": "5.78100000", "f": 199140724, "l": 199140724, "T": 1604221294655, "m": true, "M": true}, {"e": "aggTrade", "E": 1604221294859, "s": "ETHBTC", "a": 178113218, "p": "0.02817600", "q": "3.00000000", "f": 199140725, "l": 199140725, "T": 1604221294858, "m": false, "M": true}, {"e": "aggTrade", "E": 1604221307945, "s": "ETHBTC", "a": 178113219, "p": "0.02817600", "q": "0.25300000", "f": 199140726, "l": 199140726, "T": 1604221307944, "m": false, "M": true}, {"e": "aggTrade", "E": 1604221308656, "s": "ETHBTC", "a": 178113220, "p": "0.02817600", "q": "0.03900000", "f": 199140727, "l": 199140727, "T": 1604221308655, "m": false, "M": true}, {"e": "aggTrade", "E": 1604221309140, "s": "ETHBTC", "a": 178113221, "p": "0.02817500", "q": "0.00500000", "f": 199140728, "l": 199140728, "T": 1604221309139, "m": true, "M": true}, {"e": "aggTrade", "E": 1604221324705, "s": "ETHBTC", "a": 178113222, "p": "0.02817500", "q": "2.76200000", "f": 199140729, "l": 199140729, "T": 1604221324703, "m": true, "M": true}, {"e": "aggTrade", "E": 1604221324837, "s": "ETHBTC", "a": 178113223, "p": "0.02817500", "q": "0.31900000", "f": 199140730, "l": 199140730, "T": 1604221324835, "m": true, "M": true}, {"e": "aggTrade", "E": 1604221324987, "s": "ETHBTC", "a": 178113224, "p": "0.02817500", "q": "0.07000000", "f": 199140731, "l": 199140731, "T": 1604221324985, "m": true, "M": true}, {"e": "aggTrade", "E": 1604221325616, "s": "ETHBTC", "a": 178113225, "p": "0.02817500", "q": "10.91200000", "f": 199140732, "l": 199140732, "T": 1604221325615, "m": true, "M": true}, {"e": "aggTrade", "E": 1604221336733, "s": "ETHBTC", "a": 178113226, "p": "0.02816900", "q": "3.55000000", "f": 199140733, "l": 199140733, "T": 1604221336732, "m": true, "M": true}, {"e": "aggTrade", "E": 1604221336733, "s": "ETHBTC", "a": 178113227, "p": "0.02816800", "q": "0.28300000", "f": 199140734, "l": 199140734, "T": 1604221336732, "m": true, "M": true}, {"e": "aggTrade", "E": 1604221345099, "s": "ETHBTC", "a": 178113228, "p": "0.02816600", "q": "0.13700000", "f": 199140735, "l": 199140735, "T": 1604221345098, "m": true, "M": true}, {"e": "aggTrade", "E": 1604221345099, "s": "ETHBTC", "a": 178113229, "p": "0.02816500", "q": "0.04300000", "f": 199140736, "l": 199140736, "T": 1604221345098, "m": true, "M": true}, {"e": "aggTrade", "E": 1604221345257, "s": "ETHBTC", "a": 178113230, "p": "0.02816700", "q": "5.03600000", "f": 199140737, "l": 199140738, "T": 1604221345255, "m": false, "M": true}, {"e": "aggTrade", "E": 1604221351196, "s": "ETHBTC", "a": 178113231, "p": "0.02817000", "q": "0.02900000", "f": 199140739, "l": 199140740, "T": 1604221351195, "m": false, "M": true}, {"e": "aggTrade", "E": 1604221351630, "s": "ETHBTC", "a": 178113232, "p": "0.02817400", "q": "0.05000000", "f": 199140741, "l": 199140741, "T": 1604221351629, "m": true, "M": true}, {"e": "aggTrade", "E": 1604221361036, "s": "ETHBTC", "a": 178113233, "p": "0.02817600", "q": "6.82100000", "f": 199140742, "l": 199140742, "T": 1604221361035, "m": true, "M": true}, {"e": "aggTrade", "E": 1604221361259, "s": "ETHBTC", "a": 178113234, "p": "0.02817600", "q": "0.20500000", "f": 199140743, "l": 199140743, "T": 1604221361258, "m": true, "M": true}, {"e": "aggTrade", "E": 1604221363421, "s": "ETHBTC", "a": 178113235, "p": "0.02817600", "q": "3.55000000", "f": 199140744, "l": 199140744, "T": 1604221363420, "m": true, "M": true}, {"e": "aggTrade", "E": 1604221364047, "s": "ETHBTC", "a": 178113236, "p": "0.02817600", "q": "17.87600000", "f": 199140745, "l": 199140745, "T": 160422136404
