sample_data/ETHBTC/2020-11-01T10-00-00_trades.json
[{"e": "aggTrade", "E": 1604224801124, "s": "ETHBTC", "a": 178114929, "p": "0.02820000", "q": "0.31900000", "f": 199142582, "l": 199142582, "T": 1604224801122, "m": true, "M": true}, {"e": "aggTrade", "E": 1604224801323, "s": "ETHBTC", "a": 178114930, "p": "0.02820000", "q": "18.34400000", "f": 199142583, "l": 199142583, "T": 1604224801322, "m": true, "M": true}, {"e": "aggTrade", "E": 1604224801440, "s": "ETHBTC", "a": 178114931, "p": "0.02820000", "q": "11.38500000", "f": 199142584, "l": 199142584, "T": 1604224801439, "m": true, "M": true}, {"e": "aggTrade", "E": 1604224804147, "s": "ETHBTC", "a": 178114932, "p": "0.02820300", "q": "0.57100000", "f": 199142585, "l": 199142585, "T": 1604224804146, "m": true, "M": true}, {"e": "aggTrade", "E": 1604224806109, "s": "ETHBTC", "a": 178114933, "p": "0.02820200", "q": "0.31900000", "f": 199142586, "l": 199142586, "T": 1604224806107, "m": true, "M": true}, {"e": "aggTrade", "E": 1604224806939, "s": "ETHBTC", "a": 178114934, "p": "0.02820200", "q": "0.78400000", "f": 199142587, "l": 199142587, "T": 1604224806938, "m": true, "M": true}, {"e": "aggTrade", "E": 1604224807037, "s": "ETHBTC", "a": 178114935, "p": "0.02820200", "q": "0.59200000", "f": 199142588, "l": 199142588, "T": 1604224807036, "m": true, "M": true}, {"e": "aggTrade", "E": 1604224808325, "s": "ETHBTC", "a": 178114936, "p": "0.02820300", "q": "0.33900000", "f": 199142589, "l": 199142589, "T": 1604224808323, "m": true, "M": true}, {"e": "aggTrade", "E": 1604224809362, "s": "ETHBTC", "a": 178114937, "p": "0.02820400", "q": "0.35100000", "f": 199142590, "l": 199142591, "T": 1604224809360, "m": false, "M": true}, {"e": "aggTrade", "E": 1604224810502, "s": "ETHBTC", "a": 178114938, "p": "0.02820500", "q": "4.41300000", "f": 199142592, "l": 199142592, "T": 1604224810501, "m": false, "M": true}, {"e": "aggTrade", "E": 1604224810623, "s": "ETHBTC", "a": 178114939, "p": "0.02820500", "q": "3.16400000", "f": 199142593, "l": 199142594, "T": 1604224810621, "m": false, "M": true}, {"e": "aggTrade", "E": 1604224811769, "s": "ETHBTC", "a": 178114940, "p": "0.02820600", "q": "18.57300000", "f": 199142595, "l": 199142596, "T": 1604224811767, "m": false, "M": true}, {"e": "aggTrade", "E": 1604224811881, "s": "ETHBTC", "a": 178114941, "p": "0.02820600", "q": "1.00000000", "f": 199142597, "l": 199142597, "T": 1604224811880, "m": false, "M": true}, {"e": "aggTrade", "E": 1604224811982, "s": "ETHBTC", "a": 178114942, "p": "0.02820600", "q": "14.00200000", "f": 199142598, "l": 199142599, "T": 1604224811981, "m": false, "M": true}, {"e": "aggTrade", "E": 1604224814167, "s": "ETHBTC", "a": 178114943, "p": "0.02820500", "q": "1.13000000", "f": 199142600, "l": 199142601, "T": 1604224814165, "m": false, "M": true}, {"e": "aggTrade", "E": 1604224814242, "s": "ETHBTC", "a": 178114944, "p": "0.02820500", "q": "3.44400000", "f": 199142602, "l": 199142603, "T": 1604224814241, "m": false, "M": true}, {"e": "aggTrade", "E": 1604224816472, "s": "ETHBTC", "a": 178114945, "p": "0.02820500", "q": "0.18000000", "f": 199142604, "l": 199142604, "T": 1604224816471, "m": true, "M": true}, {"e": "aggTrade", "E": 1604224816545, "s": "ETHBTC", "a": 178114946, "p": "0.02820600", "q": "1.05800000", "f": 199142605, "l": 199142605, "T": 1604224816544, "m": false, "M": true}, {"e": "aggTrade", "E": 1604224821609, "s": "ETHBTC", "a": 178114947, "p": "0.02820500", "q": "0.03600000", "f": 199142606, "l": 199142606, "T": 1604224821607, "m": false, "M": true}, {"e": "aggTrade", "E": 1604224822705, "s": "ETHBTC", "a": 178114948, "p": "0.02820900", "q": "0.26800000", "f": 199142607, "l": 199142607, "T": 1604224822704, "m": true, "M": true}, {"e": "aggTrade", "E": 1604224822708, "s": "ETHBTC", "a": 178114949, "p": "0.02820900", "q": "0.33700000", "f": 199142608, "l": 199142608, "T": 1604224822707, "m": true, "M": true}, {"e": "aggTrade", "E": 1604224827817, "s": "ETHBTC", "a": 178114950, "p": "0.02820800", "q": "5.70100000", "f": 199142609, "l": 199142609, "T": 1604224827816, "m": true, "M": true}, {"e": "aggTrade", "E": 1604224829540, "s": "ETHBTC", "a": 178114951, "p": "0.02820700", "q": "0.00500000", "f": 199142610, "l": 199142610, "T": 1604224829539, "m": true, "M": true}, {"e": "aggTrade", "E": 1604224832661, "s": "ETHBTC", "a": 178114952, "p": "0.02820100", "q": "15.98900000", "f": 199142611, "l": 199142611, "T": 1604224832660, "m": true, "M": true}, {"e": "aggTrade", "E": 1604224832766, "s": "ETHBTC", "a": 178114953, "p": "0.02820100", "q": "8.70900000", "f": 199142612, "l": 199142612, "T": 1604224832764, "m": true, "M": true}, {"e": "aggTrade", "E": 1604224833179, "s": "ETHBTC", "a": 178114954, "p": "0.02820200", "q": "0.81100000", "f": 199142613, "l": 199142613, "T": 1604224833178, "m": true, "M": true}, {"e": "aggTrade", "E": 1604224833179, "s": "ETHBTC", "a": 178114955, "p": "0.02820100", "q": "1.27400000", "f": 199142614, "l": 199142614, "T": 1604224833178, "m": true, "M": true}, {"e": "aggTrade", "E": 1604224836530, "s": "ETHBTC", "a": 178114956, "p": "0.02820200", "q": "0.31900000", "f": 199142615, "l": 199142615, "T": 1604224836528, "m": true, "M": true}, {"e": "aggTrade", "E": 1604224836630, "s": "ETHBTC", "a": 178114957, "p": "0.02820200", "q": "0.35400000", "f": 199142616, "l": 199142616, "T": 1604224836628, "m": true, "M": true}, {"e": "aggTrade", "E": 1604224837064, "s": "ETHBTC", "a": 178114958, "p": "0.02820200", "q": "0.48500000", "f": 199142617, "l": 199142617, "T": 1604224837063, "m": true, "M": true}, {"e": "aggTrade", "E": 1604224837901, "s": "ETHBTC", "a": 178114959, "p": "0.02820200", "q": "0.06000000", "f": 199142618, "l": 199142618, "T": 1604224837899, "m": true, "M": true}, {"e": "aggTrade", "E": 1604224839161, "s": "ETHBTC", "a": 178114960, "p": "0.02820100", "q": "7.65200000", "f": 199142619, "l": 199142619, "T": 1604224839160, "m": true, "M": true}, {"e": "aggTrade", "E": 1604224841985, "s": "ETHBTC", "a": 178114961, "p": "0.02820200", "q": "0.56000000", "f": 199142620, "l": 199142620, "T": 1604224841983, "m": true, "M": true}, {"e": "aggTrade", "E": 1604224853252, "s": "ETHBTC", "a": 178114962, "p": "0.02820100", "q": "3.00000000", "f": 199142621, "l": 199142621, "T": 1604224853251, "m": true, "M": true}, {"e": "aggTrade", "E": 1604224854954, "s": "ETHBTC", "a": 178114963, "p": "0.02820200", "q": "1.56300000", "f": 199142622, "l": 199142622, "T": 1604224854952, "m": true, "M": true}, {"e": "aggTrade", "E": 1604224856393, "s": "ETHBTC", "a": 178114964, "p": "0.02820300", "q": "9.52200000", "f": 199142623, "l": 199142623, "T": 1604224856392, "m": false, "M": true}, {"e": "aggTrade", "E": 1604224859855, "s": "ETHBTC", "a": 178114965, "p": "0.02819900", "q": "0.23000000", "f": 199142624, "l": 199142624, "T": 1604224859854, "m": true, "M": true}, {"e": "aggTrade", "E": 1604224859964, "s": "ETHBTC", "a": 178114966, "p": "0.02819900", "q": "0.31900000", "f": 199142625, "l": 199142625, "T": 1604224859962, "m": true, "M": true}, {"e": "aggTrade", "E": 1604224861008, "s": "ETHBTC", "a": 178114967, "p": "0.02820000", "q": "1.00000000", "f": 199142626, "l": 199142626, "T": 1604224861006, "m": false, "M": true}, {"e": "aggTrade", "E": 1604224861108, "s": "ETHBTC", "a": 178114968, "p": "0.02820100", "q": "1.00000000", "f": 199142627, "l": 199142627, "T": 1604224861107, "m": false, "M": true}, {"e": "aggTrade", "E": 1604224861669, "s": "ETHBTC", "a": 178114969, "p": "0.02820200", "q": "0.16000000", "f": 199142628, "l": 199142628, "T": 1604224861667, "m": true, "M": true}, {"e": "aggTrade", "E": 1604224861840, "s": "ETHBTC", "a": 178114970, "p": "0.02820300", "q": "0.81500000", "f": 199142629, "l": 199142630, "T": 1604224861838, "m": false, "M": true}, {"e": "aggTrade", "E": 1604224861972, "s": "ETHBTC", "a": 178114971, "p": "0.02820500", "q": "0.17900000", "f": 199142631, "l": 199142631, "T": 1604224861970, "m": true, "M": true}, {"e": "aggTrade", "E": 1604224863525, "s": "ETHBTC", "a": 178114972, "p": "0.02820500", "q": "0.31900000", "f": 199142632, "l": 199142632, "T": 1604224863
